Workbook
Name ExtraMonthlySavings: Simulator!$E$19
Name GapAtTarget: Simulator!$E$13
Name YearsPlusMinus: Simulator!$E$16

Sheet Simulator
A1: Financial Freedom Simulator Inputs
G2: Sensitivity analysis
A3: Field Name | B3: Value | D3: Summary | G3: Annual Return | H3: Sens. Ending Capital at target Age | I3: Meets Required? | J3: How many more years till you reached required capital
A4: Current Age (years) | B4: 45 | D4: Inflation-adj. monthly income at target (€): | E4: =B8*(1+B7)^(B5-B4) -> 4457.8422 | H4: =E9 -> 876848.55
A5: Target Age for Financial Freedom (years) | B5: 65 | D5: Required Capital at target age (€): | E5: =E4*12/B13 -> 891568.44 | G5: 0.06 | H5: 516356.42 | I5: =IF(H5>=E5,"Yes","No") -> No | J5: =$B$5-INDEX($B$24:$B$80, MATCH(H5, $G$24:$G$80, 1)) -> 5
A6: Current Monthly Net Income (€) | B6: 2500 | D6: Total capital contribution | E6: =SUMIFS(H24:H104, B24:B104, "<=" & $B$5) -> 314593.78 | G6: 0.07 | H6: 572096.9 | I6: =IF(H6>=E5,"Yes","No") -> No | J6: =$B$5-INDEX($B$24:$B$80, MATCH(H6, $G$24:$G$80, 1)) -> 4
A7: Inflation Rate (% per year) | B7: 0.02 | D7: Total return | E7: =E5-E6 -> 576974.66 | G7: 0.08 | H7: 635001.95 | I7: =IF(H7>=E5,"Yes","No") -> No | J7: =$B$5-INDEX($B$24:$B$80, MATCH(H7, $G$24:$G$80, 1)) -> 3
A8: Desired Monthly Income at Freedom (€ today’s) | B8: 3000 | G8: 0.09 | H8: 706022.29 | I8: =IF(H8>=E5,"Yes","No") -> No | J8: =$B$5-INDEX($B$24:$B$80, MATCH(H8, $G$24:$G$80, 1)) -> 2
A9: Current Monthly Savings (€) | B9: 1000 | D9: Ending capital at target Age | E9: =VLOOKUP((B5-B4),A24:F80,3,FALSE) -> 876848.55 | G9: 0.1 | H9: 786232.88 | I9: =IF(ROUNDUP(H9,-3) >= ROUNDUP(E5,-3), "Yes", "No") -> No | J9: =$B$5-INDEX($B$24:$B$80, MATCH(H9, $G$24:$G$80, 1)) -> 2
A10: % of Monthly income saved | B10: =B9/B6 -> 0.4 | D10: Total capital contribution | E10: =SUMIFS(D24:D104, B24:B104, "<=" & $B$5) -> 309399.81 | G10: 0.11 | H10: 876848.55 | I10: =IF(H10>=E5,"Yes","No") -> No | J10: =$B$5-INDEX($B$24:$B$80, MATCH(H10, $G$24:$G$80, 1)) -> 1
A11: Annual Savings Increase (% per year) | B11: 0.02 | D11: Total return | E11: =E9-E10 -> 567448.75 | G11: 0.12 | H11: 979241.48 | I11: =IF(H11>=E5,"Yes","No") -> Yes | J11: =$B$5-INDEX($B$24:$B$80, MATCH(H11, $G$24:$G$80, 1)) -> 0
A12: Annual Investment Return Rate (% per year) | B12: 0.11 | F12: variation (rule) | G12: 0.13 | H12: 1094960.8 | I12: =IF(H12>=E5,"Yes","No") -> Yes | J12: =$B$5-INDEX($B$24:$B$80, MATCH(H12, $G$24:$G$80, 1)) -> -1
A13: Safe Withdrawal Rate (% per year) | B13: 0.06 | D13: Gap/Surplus at target (€): | E13: =VLOOKUP(B5,B24:F80,2,FALSE)-E5 -> -14719.886 | F13: =GapAtTarget/E5 -> -0.016510102
A14: Starting capital | B14: 0 | D14: At this pace you will retire at | E14: =INDEX(B24:B80, MATCH(E5, C24:C80, 1))+1 -> 66
D15: Instead of (your target) | E15: =B5 -> 65
D16: Years ± Freedom (at current pace): | E16: =E14-E15 -> 1 | F16: when negative you retire earlier by x, if positive you retire later by x
A17: When
A18: Capital withdrawal | D18: Target monthly savings | E18: =MAX(0,MAX(0,(E5-(C25*(1+$B$12)^($B$5-$B$4)))/(((1+$B$12)^($B$5-$B$4)-(1+$B$11)^($B$5-$B$4))/($B$12-$B$11))/12)) -> 1016.7873
A19: When | D19: Additional Monthly Savings Required (€): | E19: =MAX(0,MAX(0,(E5-(C25*(1+$B$12)^($B$5-$B$4)))/(((1+$B$12)^($B$5-$B$4)-(1+$B$11)^($B$5-$B$4))/($B$12-$B$11))/12)-B9) -> 16.787261
D20: or Additional Capital required | E20: =MAX(0,(E5-((C25*(1+$B$12)^($B$5-$B$4))+($D$25*((1+$B$12)^($B$5-$B$4)-(1+$B$11)^($B$5-$B$4))/($B$12-$B$11))))/(1+$B$12)^($B$5-$B$4)) -> 1825.7649
C23: Your Plan | G23: Your target
A24: Year | B24: Age | C24: Starting Capital (€) | D24: Annual Savings (€) | E24: Annual Returns (€) | F24: Ending Capital (€) | G24: Starting Capital (€) | H24: Annual Savings (€) | I24: Annual Returns (€) | J24: Required ending capital | K24: Required capital benchmark
A25: 0 | B25: =$B$4 + A25 -> 45 | C25: =B14 -> 0 | D25: =B9*12 -> 12000 | E25: =C25*B12 -> 0 | F25: =C25+D25+E25 -> 12000 | G25: =C25 -> 0 | H25: =E18*12 -> 12201.447 | I25: =G25*$B$12 -> 0 | J25: =G25+H25+I25 -> 12201.447 | K25: =$E$5 -> 891568.44
A26: =A25+1 -> 1 | B26: =$B$4 + A26 -> 46 | C26: =F25 -> 12000 | D26: =D25*(1+B11) -> 12240 | E26: =C26*B12 -> 1320 | F26: =C26+D26+E26 -> 25560 | G26: =J25 -> 12201.447 | H26: =H25*(1+$B$11) -> 12445.476 | I26: =G26*$B$12 -> 1342.1592 | J26: =G26+H26+I26 -> 25989.082 | K26: =$E$5 -> 891568.44
A27: =A26+1 -> 2 | B27: =$B$4 + A27 -> 47 | C27: =F26 -> 25560 | D27: =D26*(1+B11) -> 12484.8 | E27: =C27*B12 -> 2811.6 | F27: =C27+D27+E27 -> 40856.4 | G27: =J26 -> 25989.082 | H27: =H26*(1+$B$11) -> 12694.386 | I27: =G27*$B$12 -> 2858.7991 | J27: =G27+H27+I27 -> 41542.267 | K27: =$E$5 -> 891568.44
A28: =A27+1 -> 3 | B28: =$B$4 + A28 -> 48 | C28: =F27 -> 40856.4 | D28: =D27*(1+B11) -> 12734.496 | E28: =C28*B12 -> 4494.204 | F28: =C28+D28+E28 -> 58085.1 | G28: =J27 -> 41542.267 | H28: =H27*(1+$B$11) -> 12948.273 | I28: =G28*$B$12 -> 4569.6494 | J28: =G28+H28+I28 -> 59060.19 | K28: =$E$5 -> 891568.44
A29: =A28+1 -> 4 | B29: =$B$4 + A29 -> 49 | C29: =F28 -> 58085.1 | D29: =D28*(1+B11) -> 12989.186 | E29: =C29*B12 -> 6389.361 | F29: =C29+D29+E29 -> 77463.647 | G29: =J28 -> 59060.19 | H29: =H28*(1+$B$11) -> 13207.239 | I29: =G29*$B$12 -> 6496.6209 | J29: =G29+H29+I29 -> 78764.049 | K29: =$E$5 -> 891568.44
A30: =A29+1 -> 5 | B30: =$B$4 + A30 -> 50 | C30: =F29 -> 77463.647 | D30: =D29*(1+B11) -> 13248.97 | E30: =C30*B12 -> 8521.0012 | F30: =C30+D30+E30 -> 99233.618 | G30: =J29 -> 78764.049 | H30: =H29*(1+$B$11) -> 13471.384 | I30: =G30*$B$12 -> 8664.0454 | J30: =G30+H30+I30 -> 100899.48 | K30: =$E$5 -> 891568.44
A31: =A30+1 -> 6 | B31: =$B$4 + A31 -> 51 | C31: =F30 -> 99233.618 | D31: =D30*(1+B11) -> 13513.949 | E31: =C31*B12 -> 10915.698 | F31: =C31+D31+E31 -> 123663.26 | G31: =J30 -> 100899.48 | H31: =H30*(1+$B$11) -> 13740.811 | I31: =G31*$B$12 -> 11098.943 | J31: =G31+H31+I31 -> 125739.23 | K31: =$E$5 -> 891568.44
A32: =A31+1 -> 7 | B32: =$B$4 + A32 -> 52 | C32: =F31 -> 123663.26 | D32: =D31*(1+B11) -> 13784.228 | E32: =C32*B12 -> 13602.959 | F32: =C32+D32+E32 -> 151050.45 | G32: =J31 -> 125739.23 | H32: =H31*(1+$B$11) -> 14015.627 | I32: =G32*$B$12 -> 13831.316 | J32: =G32+H32+I32 -> 153586.18 | K32: =$E$5 -> 891568.44
A33: =A32+1 -> 8 | B33: =$B$4 + A33 -> 53 | C33: =F32 -> 151050.45 | D33: =D32*(1+B11) -> 14059.913 | E33: =C33*B12 -> 16615.55 | F33: =C33+D33+E33 -> 181725.91 | G33: =J32 -> 153586.18 | H33: =H32*(1+$B$11) -> 14295.94 | I33: =G33*$B$12 -> 16894.479 | J33: =G33+H33+I33 -> 184776.59 | K33: =$E$5 -> 891568.44
A34: =A33+1 -> 9 | B34: =$B$4 + A34 -> 54 | C34: =F33 -> 181725.91 | D34: =D33*(1+B11) -> 14341.111 | E34: =C34*B12 -> 19989.851 | F34: =C34+D34+E34 -> 216056.88 | G34: =J33 -> 184776.59 | H34: =H33*(1+$B$11) -> 14581.859 | I34: =G34*$B$12 -> 20325.425 | J34: =G34+H34+I34 -> 219683.88 | K34: =$E$5 -> 891568.44
A35: =A34+1 -> 10 | B35: =$B$4 + A35 -> 55 | C35: =F34 -> 216056.88 | D35: =D34*(1+B11) -> 14627.933 | E35: =C35*B12 -> 23766.256 | F35: =C35+D35+E35 -> 254451.06 | G35: =J34 -> 219683.88 | H35: =H34*(1+$B$11) -> 14873.496 | I35: =G35*$B$12 -> 24165.227 | J35: =G35+H35+I35 -> 258722.6 | K35: =$E$5 -> 891568.44
A36: =A35+1 -> 11 | B36: =$B$4 + A36 -> 56 | C36: =F35 -> 254451.06 | D36: =D35*(1+B11) -> 14920.492 | E36: =C36*B12 -> 27989.617 | F36: =C36+D36+E36 -> 297361.17 | G36: =J35 -> 258722.6 | H36: =H35*(1+$B$11) -> 15170.966 | I36: =G36*$B$12 -> 28459.486 | J36: =G36+H36+I36 -> 302353.05 | K36: =$E$5 -> 891568.44
A37: =A36+1 -> 12 | B37: =$B$4 + A37 -> 57 | C37: =F36 -> 297361.17 | D37: =D36*(1+B11) -> 15218.902 | E37: =C37*B12 -> 32709.729 | F37: =C37+D37+E37 -> 345289.8 | G37: =J36 -> 302353.05 | H37: =H36*(1+$B$11) -> 15474.385 | I37: =G37*$B$12 -> 33258.836 | J37: =G37+H37+I37 -> 351086.27 | K37: =$E$5 -> 891568.44
A38: =A37+1 -> 13 | B38: =$B$4 + A38 -> 58 | C38: =F37 -> 345289.8 | D38: =D37*(1+B11) -> 15523.28 | E38: =C38*B12 -> 37981.878 | F38: =C38+D38+E38 -> 398794.96 | G38: =J37 -> 351086.27 | H38: =H37*(1+$B$11) -> 15783.873 | I38: =G38*$B$12 -> 38619.49 | J38: =G38+H38+I38 -> 405489.64 | K38: =$E$5 -> 891568.44
A39: =A38+1 -> 14 | B39: =$B$4 + A39 -> 59 | C39: =F38 -> 398794.96 | D39: =D38*(1+B11) -> 15833.745 | E39: =C39*B12 -> 43867.446 | F39: =C39+D39+E39 -> 458496.15 | G39: =J38 -> 405489.64 | H39: =H38*(1+$B$11) -> 16099.55 | I39: =G39*$B$12 -> 44603.86 | J39: =G39+H39+I39 -> 466193.05 | K39: =$E$5 -> 891568.44
A40: =A39+1 -> 15 | B40: =$B$4 + A40 -> 60 | C40: =F39 -> 458496.15 | D40: =D39*(1+B11) -> 16150.42 | E40: =C40*B12 -> 50434.577 | F40: =C40+D40+E40 -> 525081.15 | G40: =J39 -> 466193.05 | H40: =H39*(1+$B$11) -> 16421.541 | I40: =G40*$B$12 -> 51281.235 | J40: =G40+H40+I40 -> 533895.82 | K40: =$E$5 -> 891568.44
A41: =A40+1 -> 16 | B41: =$B$4 + A41 -> 61 | C41: =F40 -> 525081.15 | D41: =D40*(1+B11) -> 16473.428 | E41: =C41*B12 -> 57758.927 | F41: =C41+D41+E41 -> 599313.51 | G41: =J40 -> 533895.82 | H41: =H40*(1+$B$11) -> 16749.972 | I41: =G41*$B$12 -> 58728.541 | J41: =G41+H41+I41 -> 609374.34 | K41: =$E$5 -> 891568.44
A42: =A41+1 -> 17 | B42: =$B$4 + A42 -> 62 | C42: =F41 -> 599313.51 | D42: =D41*(1+B11) -> 16802.897 | E42: =C42*B12 -> 65924.486 | F42: =C42+D42+E42 -> 682040.89 | G42: =J41 -> 609374.34 | H42: =H41*(1+$B$11) -> 17084.972 | I42: =G42*$B$12 -> 67031.177 | J42: =G42+H42+I42 -> 693490.49 | K42: =$E$5 -> 891568.44
...

Sheet Interpretation
A1: FINANCIAL INDEPENDENCE
A3: Your desired monthly income at retirement is | B3: =Simulator!B8 -> 3000
A4: however if you take into account the rise in prices by the time you get to retirement you ll need to earn a monthly income of | B4: =Simulator!E4 -> 4457.8422
A6: To be able to earn your desired monthly income of | B6: =Simulator!E4 -> 4457.8422
A7: You will need to accumulate a capital of | B7: =Simulator!E5 -> 891568.44
A8: By your desired retirement age | B8: =Simulator!B5 -> 65
A10: Why? Because you can live safe with interest only (Benchmarked at 6%) without the need of depleting your capital, you don't know the age of your death thus the safest bet is only to live off interest earned on your placement without using your capital
A13: Your current plan shows that you will accumulate a capital of | B13: =Simulator!E9 -> 876848.55
A14: And that you need +/- years to reach required capital | B14: =YearsPlusMinus -> 1 | C14: (positive means more years required, negative means less years required)
A15: at age | B15: =Simulator!E14 -> 66
A18: Your planned monthly savings is | B18: =Simulator!B9 -> 1000
A19: Your target monthly saving is | B19: =Simulator!E18 -> 1016.7873
A22: Variations compared required and planned | B22: =Simulator!F13 -> -0.016510102

Sheet Rules variations & narratives
B2: Variations compared required and planned | C2: =Interpretation!B22 -> -0.016510102
B5: % Gap vs Benchmark (EN) | C5: Écart % vs Repère (FR) | D5: Situation (EN) | E5: Situation (FR) | F5: Narrative (EN) | G5: Narratif (FR) | H5: Suggested Actions (EN) | I5: Actions suggérées (FR)
B6: ≥ +20% above benchmark | C6: ≥ +20 % au-dessus du repère | D6: You are way ahead | E6: Vous êtes largement en avance | F6: 🎉 Fantastic news! You’re ahead of schedule — your future self will thank you. | G6: 🎉 Excellente nouvelle ! Vous avez de l’avance — votre « vous » du futur vous dira merci. | H6: You can reduce monthly savings a bit or retire earlier; reinvest the surplus. | I6: Vous pouvez réduire un peu l’épargne mensuelle ou avancer la retraite ; réinvestissez l’excédent.
B7: +5% to +20% above | C7: De +5 % à +20 % au-dessus | D7: Comfortably on target | E7: Confortablement dans l’objectif | F7: 😊 Well done! You’ve built a nice cushion — enjoy the view without stress. | G7: 😊 Bravo ! Beau coussin de sécurité — profitez sereinement. | H7: Keep your rhythm; add occasional bonus contributions when income allows. | I7: Gardez le rythme ; ajoutez des « bonus » quand les revenus le permettent.
B8: −5% to +5% (very close) | C8: De −5 % à +5 % (très proche) | D8: Right on track | E8: Sur la bonne trajectoire | F8: 👍 You’re basically there — a tiny push locks it in. | G8: 👍 Vous y êtes presque — un petit coup de pouce et c’est acquis. | H8: Slightly increase monthly savings or add a one-time boost. | I8: Augmentez légèrement l’épargne mensuelle ou faites un apport ponctuel.
B9: −5% to −20% (slightly behind) | C9: De −5 % à −20 % (léger retard) | D9: Close, needs a nudge | E9: Proche, besoin d’un petit élan | F9: 👀 Very close — think “one more step up the stairs.” | G9: 👀 Très proche — pensez « une marche de plus ». | H9: Lift savings by 5–10%; plan to grow your saving % as income rises. | I9: Montez l’épargne de 5–10 % ; prévoyez d’augmenter le % d’épargne avec les revenus.
B10: −20% to −40% (moderately behind) | C10: De −20 % à −40 % (retard modéré) | D10: Noticeable gap | E10: Écart notable | F10: ⚡ There’s a gap, but it’s fixable — like catching the next bus. | G10: ⚡ Écart rattrapable — comme prendre le prochain bus. | H10: Boost monthly savings now; consider an initial contribution. | I10: Augmentez l’épargne dès maintenant ; envisagez un apport initial.
B11: −40% to −60% (significant gap) | C11: De −40 % à −60 % (retard important) | D11: Well behind | E11: En retard | F11: 💡 Looks big, but don’t panic — mid-marathon pace changes work. | G11: 💡 Écart important, mais pas de panique — on ajuste le rythme en cours de route. | H11: Strongly increase savings; add initial capital; consider a slightly later retirement. | I11: Augmentez significativement l’épargne ; ajoutez un apport ; envisagez de décaler un peu la retraite.
B12: −60% to −80% (very behind) | C12: De −60 % à −80 % (retard marqué) | D12: Serious shortfall | E12: Fort retard | F12: 🚨 We need a new game plan — your GPS is recalculating, and there’s still a route. | G12: 🚨 Nouveau plan nécessaire — le GPS recalcule, il y a encore un itinéraire. | H12: Aggressively raise savings, add capital, and extend the horizon if needed. | I12: Augmentez fortement l’épargne, ajoutez du capital et allongez l’horizon si besoin.
B13: −80% or more (far behind) | C13: −80 % ou plus (écart critique) | D13: Critical shortfall | E13: Écart critique | F13: ❤️ It may look shocking, but you’re not alone. Best time to plant a tree was 20 years ago; second best is today 🌱. Start now. | G13: ❤️ C’est impressionnant, mais vous n’êtes pas seul. Le meilleur moment pour planter un arbre était il y a 20 ans ; le deuxième, c’est aujourd’hui 🌱. Commençons. | H13: Restart with a higher savings plan, add initial capital, commit to steady increases. | I13: Reprenez avec une épargne plus élevée, ajoutez un apport initial, engagez-vous sur des hausses régulières.
